Workbook

Sheet Trial Bal
A1: RAMSON & GRANDSON JEWELLERS PVT. LTD. 1-4-20
A2: CIN: U52393AP2011PTC072492
A3: Trial Balance
A4: 1-Apr-21 to 31-Mar-22
B5: RAMSON & GRANDSON JEWELLERS PVT. LTD. - (from 1-Apr-2019) - (from 1-Apr-20)
A6: Particulars | B6: 1-Apr-21 to 31-Mar-22
B7: Closing Balance
B8: Debit | C8: Credit
A9: Capital Account
A10: Share Capital A/c.
A11: Share Capital A/c.
A12: Reserves & Surplus
A13: Reserves and Surplus
A14: Share Premium A/c.
A15: Loans (Liability)
A16: Unsecured Loans
A17: G. Aruna
A18: G. Krishna
A19: G. Krupan Kumar
A20: Current Liabilities
... A91: Grand Total

Sheet TB2023
A1: RAMSON & GRANDSON JEWELLERS PVT. LTD.
A2: CIN: U52393AP2011PTC072492
A3: Trial Balance
A4: 1-Apr-22 to 31-Mar-23
B5: RAMSON & GRANDSON JEWELLERS PVT. LTD. - (from 1-4-22)
A6: Particulars | B6: 1-Apr-22 to 31-Mar-23
B7: Closing Balance
B8: Debit | C8: Credit
A9: Capital Account
A10: Share Capital A/c.
A11: Reserves & Surplus
A12: Loans (Liability)
A13: Unsecured Loans
A14: Current Liabilities
A15: Duties & Taxes
A16: Sundry Creditors
A17: Other Current Liabilities
A18: Fixed Assets
A19: Computers & Data Processing Units
A20: Office Equipment
... A49: Employee Benefit Expenses
A50: Other Expenses | C50: =26.89+4
A51: Chirayu Software
A52: C S R Expences
A53: Depreciation
A54: Discount Allowed
A55: Interest on TDS and TCS
A56: Miscelenious Expenses
A57: Sales Permotion Exp.
A58: Software Expenses
A59: Profit & Loss A/c
A60: Grand Total

Sheet Sch III Ratios
A2: 26. Following are the Analytical ratios for the year ended March 31, 2023 and March 31, 2022
A3: Ratio | B3: Numerator | C3: Denominator | D3: As at 31-03-2023 | E3: As at 31-03-2022 | F3: As at 31-03-2021 | G3: Variation % | H3: Reason for Variation ( if change is more than25%
A4: Current ratio (Times) | B4: current assets | C4: current Laibilities | D4: =(BS!C23+BS!C24+BS!C25+BS!C26)/(BS!C12+BS!C13) | E4: =(BS!D23+BS!D24+BS!D25+BS!D26)/(BS!D12+BS!D13) | F4: =(BS!E23+BS!E24+BS!E25+BS!E26)/(BS!E12+BS!E13) | G4: =E4-D4 | H4: Variation < than 25% | L4: =E4-F4
A5: Debt equity ratio (Times) | B5: Total debts | C5: Shareholders Equity | D5: =BS!C10/(BS!C7+BS!C8) | E5: =BS!D10/(BS!D7+BS!D8) | F5: =BS!E10/(BS!E7+BS!E8) | G5: =E5-D5 | L5: =E5-F5
A6: Debt service covberage ratio ( Times) | B6: Earning available for debt service | C6: Debt service | D6: NA | E6: NA | F6: ='P&L'!E20/'P&L'!E16 | H6: NA | L6: =E6-F6
A7: Return on equity ratio % | B7: profit for the year after tax | C7: Average shareholders equity | D7: ='P&L'!C24/BS!C7 | E7: ='P&L'!D24/BS!D7 | F7: ='P&L'!E24/BS!E7 | G7: =E7-D7 | H7: Variation < than 25% | L7: =E7-F7
A8: Inventory turnover ratio | B8: Cost of goods sold | C8: Average Inventory | D8: =('P&L'!C10+'P&L'!C11+'P&L'!C13)/BS!J23 | E8: =('P&L'!D10+'P&L'!D11+'P&L'!D13)/BS!K23 | F8: =('P&L'!E10+'P&L'!E11+'P&L'!E13)/BS!L23 | G8: =E8-D8 | H8: due to increase in average inventoruy | L8: =E8-F8
A9: Trade receivables turnover ratio | B9: Revanue from operation | C9: Average trade receivable | D9: ='P&L'!C5/BS!J24 | E9: ='P&L'!D5/BS!K24 | F9: ='P&L'!E5/BS!L24 | G9: =E9-D9 | H9: increase in average trade receivables | L9: =E9-F9
A10: Trade payable turnover ratio | B10: Revanue from operation | C10: Average trade payable | D10: ='P&L'!C5/BS!J12 | E10: ='P&L'!D5/BS!K12 | F10: ='P&L'!E5/BS!L12 | G10: =E10-D10 | H10: incease in average payable | L10: =E10-F10
A11: Net capital turnover ratio | B11: revanue from operation | C11: average working capital | D11: ='P&L'!C5/BS!K28 | E11: ='P&L'!D5/BS!L28 | F11: ='P&L'!E5/BS!M28 | G11: =E11-D11 | H11: due to increase in average working capital | L11: =E11-F11
A12: Net profit ratio % | B12: Profit for the year after tax | C12: Revanue from operation | D12: ='P&L'!C24/'P&L'!C7 | E12: ='P&L'!D24/'P&L'!D5 | F12: ='P&L'!E24/'P&L'!E5 | G12: =E12-D12 | H12: No variation | L12: =E12-F12
A13: Return on capital Employed % | B13: Profit before Tax+finance cost | C13: capital employed | D13: =('P&L'!C20+'P&L'!C16)/BS!K9 | E13: =('P&L'!D20+'P&L'!D16)/BS!L9 | F13: =('P&L'!E20+'P&L'!E16)/BS!M9 | G13: =E13-D13 | H13: Variation < than 25% | L13: =E13-F13
A14: Return on investment % | B14: income from investment | C14: Average investment | E14: NA | F14: NA | H14: NA
A19: Earning available for debt service | B19: Profit before interest and tax
A20: Debt service | B20: Interest expense +repayment of loanduring the year
A21: capital employed | B21: Average equity and average loan fund
A22: income from investment | B22: profit on sale of investment , dividend and interest
A23: Average investment | B23: Includes current investment, inter corporate deposit and fixed deposit
A24: Return on investment a | B24: Return on investment is relating to fixed deposits. As regards Investment in shares of Patancheru Enivrotech Ltd. There is no return on this investment and hence not taken in calculation
A27: As per our report of even date
A28: For O M N & Associates
A29: Chartered Accountants | E29: Director
A30: ( Firm regn. No. 000383S) | E30: G Krishna
E31: DIN: 03336421 | F31: Director
F32: G Krishna
A33: Om Prakash Bang | F33: DIN: 03336421
A34: Partner | E34: Director
A35: Membership No. 018948 | E35: G Krupan
A36: Place: Hyderabad | E36: DIN : 03363685 | F36: Director
A37: =BS!A41 | F37: G Krupan
A38: UDIN: | F38: DIN : 03363685
A50: Average shareholders equity | B50: Op bal+Cl bal/2
A51: average working capital | B51: Op+Cl/2
A52: Average Inventory | B52: Op bal+Cl bal/2
A53: Average trade receivable | B53: Op bal+Cl bal/2
A54: Average trade payable | B54: Op bal+Cl bal/2
A55: Average investment | B55: Op bal+Cl bal/2

Sheet Sheet2
A1: Discloser of Trade payable
A2: Forming part of Note trade payable
A3: Discloser for the Financial year 2022-23
A4: Particulars | C4: Outstanding for following peroid from
C5: due date of payment | F5: Total
B6: < 1 year | C6: 1-2 years | D6: 2-3 years | E6: > 3years
A7: (i) MSME
A8: (ii) Others | B8: =Notes!D51 | F8: =B8+C8+D8+E8
A9: (iii) Disputed dues MSME
A10: (iv) Disputed Dues Others
A11: Total | B11: =SUM(B7:B10) | C11: =SUM(C7:C10) | D11: =SUM(D7:D10) | E11: =SUM(E7:E10) | F11: =SUM(F7:F10)
A12: Discloser for the Financial year 2021-22
A13: Particulars | C13: Outstanding for following peroid from
C14: due date of payment | F14: Total
B15: < 1 year | C15: 1-2 years | D15: 2-3 years | E15: > 3years
A16: (i) MSME
A17: (ii) Others | B17: =Notes!F51 | F17: =B17
A18: (iii) Disputed dues MSME
A19: (iv) Disputed Dues Others
A20: Total | B20: =SUM(B16:B19) | C20: =SUM(C16:C19) | F20: =SUM(F16:F19)
A27: Forming part of Note Trade receivable
A28: Trade receivables Aging schedule
B29: Outstanding for following peroid from
B30: due date of receivables for the finamncial year 2022-23
B31: < Six months | C31: Six months -1 year | D31: 1-2 years | E31: 2-3 years | F31: > 3years | G31: Total
A32: (i) Undisputed Trade | G32: =B32+C32+D32+I32+F32
A33: receivables
A34: Considered good | B34: =Notes!D76 | G34: =B34
A35: (ii) Undisputed Trade | G35: =B35+C35+D35+I35+F35
A36: receivables
A37: Considered doubtful
A38: (iii) Disputed Trade | G38: =B38+C38+D38+I38+F38
A39: receivables
A40: Considered good
A41: (iv) Disputed Trade | G41: =B41+C41+D41+I41+F41
A42: receivables
A43: Considered doubtful
B46: Outstanding for following peroid from
B47: due date of receivables for the finamncial year 2021-22
B48: < Six months | C48: Six months -1 year | D48: 1-2 years | E48: 2-3 years | F48: > 3years | G48: Total
...

Sheet Sub Grouping
A2: Other payable | D2: 45016
A4: TCS | E4: ='Trial Bal'!C23
A5: TDS Creditors | E5: ='Trial Bal'!C25
A6: ='Trial Bal'!A28 | D6: ='TB2023'!C17+30000 | E6: ='Trial Bal'!C28+30000
A7: Provision for CSR
D8: =SUM(D4:D7) | E8: =SUM(E4:E7)
A10: I T Refundable
A11: 21-22 | D11: ='TB2023'!B30
A12: 22-23 | D12: =15988100.8-'P&L'!C22
D14: =SUM(D11:D12)
A16: GST Refundable
A17: CGST @ 1.5%
A18: SGST @ 1.5%
D19: =SUM(D17:D18)
A22: Other income
A23: Discount Recd. A/c. | D23: ='TB2023'!C46
A24: Interest on IT Refund | D24: ='TB2023'!C47
A25: ='TB2023'!A53
D26: =SUM(D23:D25)

Sheet Notes
B1: RAMSON AND GRANDSON JEWELLERS PRIVATE LIMITED
A2: Note | B2: Notes on Financial Statements for the year ended 31st March 2023
A3: No. | C3: As At March 2023 | E3: As at March 2022 | G3: As at March 2021 | I3: As At 31st March 2020
B4: SHARE CAPITAL
B5: Authorised Capital
B6: 5,00,000 Equity shares of Rs. 10/- each | F6: =H6
B8: Issued, Subscribed and paid up Capital
B9: 1,30,000 (1,30,000) Equity shares of Rs. 10/- each | D9: ='TB2023'!C10 | F9: =H9 | H9: =[1]TB2021!O62 | J9: ='[1]TB 2020'!C13
D10: =SUM(D9:D9) | F10: =F9 | H10: =SUM(H9) | J10: =SUM(J9)
B11: 2.1 The details Shareholders holding more than 5% Shares:
B12: Name of the share holder
C13: No. of shares | D13: % of Total Shares | E13: No. of shares | F13: % of Total Shares
B14: Aruna Guggila | C14: =E14 | E14: =G14 | F14: =H14 | H14: =G14*100/130000 | J14: =I14*100/130000
B15: Krishna Guggila | E15: =G15 | F15: =H15 | H15: =G15*100/130000 | J15: =I15*100/130000
B16: Krupan Guggila | C16: =E16 | E16: =G16 | F16: =H16 | H16: =G16*100/130000 | J16: =I16*100/130000
B19: 2.2 The reconciliation of the number of shares outstanding is set out below:
B20: Equity shares at the beginning of the year | E20: =G20
B21: Issued during the year | E21: - | G21: - | I21: - | L21: -
B22: Equity shares at the end of the year | E22: =E20
B24: 2.3 Discloser of Shareholding of Promoters* as below
B25: Equity Shares held by promoters at the end of the year
B26: S. No. and name of Promoters | C26: No. of shares | D26: % of Total Shares | E26: No. of shares | F26: % of Total Shares | G26: % change during the year
B27: 1. Aruna Guggila
B28: 2. Krishna Guggila
B29: 3. Krupan Guggila
B31: RESERVES AND SURLPUS
B32: Share premium account
B33: As per last Balance Sheet | E33: ='Trial Bal'!C14 | G33: =[1]TB2021!O65
B34: As at Year End | D34: =C33 | F34: =E33
B36: Profit and loss account
B37: As per last Balance sheet | E37: =H40 | G37: =[1]TB2021!O64 | I37: ='[1]TB 2020'!C15
B38: Add:Appropriations- GST refund received
B39: Add: Profit for the year | C39: ='P&L'!C24 | E39: ='P&L'!D24 | G39: =[1]PL!C25 | I39: =[1]PL!D25
B40: Less: IT Paid of earlier year | E40: ='Trial Bal'!B88 | F40: =E39+E37-E40 | H40: =G37+G39
D41: =C37+C39-C40+D34 | F41: =F40+F34 | H41: =SUM(H34:H40) | J41: =I37+I39+I38+I40+J34
B42: LONG TERM BORROWINGS
C43: Non Current | D43: Current | E43: Non Current | F43: Current | G43: Non | H43: Current | I43: Non | J43: Current | L43: Non | M43: Current
G44: Current | I44: Current | L44: Current
B45: Unsecured
B46: Loans from directors | C46: ='TB2023'!C13 | E46: ='Trial Bal'!C15 | G46: ='[1]Sub Grouping'!B7 | I46: ='[1]Sub Grouping'!C7
...

Sheet Add Notes
B1: Deffered Tax Asset is related to net timing difference of depreciation.
B2: Pursuant to the enactment of the Companies Act 2013,the Company has applied
B3: the estimated useful lives as specified in Schedule II.Accordingly the unamortised
B4: carrying value is being depreciated over the remaining useful life of the assets.
B5: Previous Year figures are regrouped wherever necessary.
B6: Disclosure of Related Party Transaction as per AS 18
C7: Key Managerial Personal:
C8: Relation | E8: Person
C9: Director | E9: G Krishna
C10: Director | E10: G Aruna
C11: Director | E11: G Krupan
C12: Key Managerial Personal having Significant infulence
C13: Directors are interested in following concerns:
C14: Name of Director | E14: Interested in concern | G14: In capacity of
C15: G Krishna | E15: A K Hardware Syndicate | G15: Propreitor
C16: G Krishna,G krupan | E16: G K Infra Pvt Ltd | G16: Directors
C18: Payment/ Transactions with related parties:
C19: Name | E19: Loan | F19: Loan | G19: Year end | H19: Remuneration Paid
E20: Accepted | F20: Repaid | G20: Balance
C21: G Krishna
C22: G Krupan
C23: G Aruna
B25: During the year under review the company had the laibility of Rs.107,250/- towards CSR.
B26: expenditure on CSR during the year is NIL.
B27: There are no transactions during the year with companies struck off under section 248 of
B28: the Companies Act, 2013 or section 560 of Companies Act, 1956.
B29: There are no Loans or Advances in the nature of loans are granted to promoters,
B30: directors, KMPs and the related parties (as defined under Companies Act, 2013,)
B31: either severally or jointly with any other person.
C34: As per our report of even date
C35: =BS!A32
C36: Chartered Accountants | G36: Director
C37: ( Firm regn. No. 000383S) | G37: G Krishna
G38: DIN: 03336421
C40: Om Prakash Bang
C41: Partner | G41: Director
C42: Membership No. 018948 | G42: G Krupan
C43: Place: Hyderabad | G43: DIN : 03363685
C44: =BS!A41

Sheet BS
A1: RAMSON AND GRANDSON JEWELLERS PRIVATE LIMITED
A2: BALANCE SHEET AS AT 31-03-2023
A4: Particulars | B4: Note No. | C4: AS AT 31st March 2023 | D4: AS AT 31st March 2022 | E4: AS AT 31st March 2021 | F4: AS AT 31st March 2020
A5: I. EQUTIY AND LAIBILITY
A6: (1) Share holders funds
A7: (a) Share Capital | C7: =Notes!D10 | D7: =Notes!F10 | E7: =[1]Notes!D10 | F7: =[1]Notes!F10
A8: (b) Reserves and Surplus | C8: =Notes!D41 | D8: =Notes!F41 | E8: =[1]Notes!D34 | F8: =[1]Notes!F34 | J8: =C7+C8+C10 | K8: =D7+D8+D10 | L8: =E7+E8+E10 | M8: =H7+H8+H10
A9: (2) Non Current Laibilities | K9: =(J8+K8)/2 | L9: =(K8+L8)/2 | M9: =(L8+M8)/2
A10: (a)Long Term Borrowings | C10: =Notes!C47 | D10: =Notes!E47 | E10: =[1]Notes!C40 | F10: =[1]Notes!E40
A11: (3) Current Laibilities
A12: (a) Trade Payables | C12: =Notes!D51 | D12: =Notes!F51 | E12: =[1]Notes!D44 | F12: =[1]Notes!F44 | J12: =(C12+D12)/2 | K12: =(D12+E12)/2 | L12: =(E12+H12)/2
A13: ( b ) Other current liabilities | C13: =Notes!D60 | D13: =Notes!F60 | E13: =[1]Notes!D53 | F13: =[1]Notes!F53
A14: TOTAL | C14: =SUM(C7:C13) | D14: =SUM(D7:D13) | E14: =SUM(E7:E13)+1 | F14: =SUM(F7:F13)
A15: II. ASSETS
A16: (1) Non Current Assets
A17: (a) Fixed Assets
A18: (i) Tangible Assets | C18: ='Com Dep'!K13 | D18: ='Com Dep'!K14 | E18: ='[1]Dep as per Com Act'!K13
A19: (b) Deffered Tax Assets | C19: ='TB2023'!B28+'P&L'!C23 | D19: ='Trial Bal'!B52-'P&L'!D23 | E19: ='[1]Dep as per IT Act'!D49
A20: ( c ) Non Current Investments | D20: =Notes!F65 | F20: =[1]Notes!F60
A21: ( d ) Long term loans and Advances | D21: =Notes!F69 | E21: =[1]Notes!D64 | F21: =[1]Notes!F64
A22: (2) Current Assets
A23: (a) Inventories | C23: =Notes!D99 | D23: =Notes!F72 | E23: =[1]Notes!D67 | I23: Av inventory | J23: =(C23+D23)/2 | K23: =(D23+E23)/2 | L23: =(E23+H23)/2
A24: (b) Trade Receivables | C24: =Notes!D76 | D24: =Notes!F76 | F24: =[1]Notes!F71 | I24: Av tr rec | J24: =(C24+D24)/2 | K24: =(D24+E24)/2 | L24: =(E24+H24)/2
A25: ( c ) Cash and Bank Balances | C25: =Notes!D81 | D25: =Notes!F81 | E25: =[1]Notes!D76 | F25: =[1]Notes!F76
A26: (d) Other current assets | C26: =Notes!D92 | D26: =Notes!F92 | E26: =[1]Notes!D84
A27: TOTAL | C27: =SUM(C18:C26) | D27: =SUM(D18:D26) | E27: =SUM(E18:E26) | F27: =SUM(F18:F26) | J27: =(C23+C24+C25+C26)-(C12+C13) | K27: =(D23+D24+D25+D26)-(D12+D13) | L27: =(E23+E24+E25+E26)-(E12+E13) | M27: =(H23+H24+H25+H26)-(H12+H13)
A28: Significant accounting policies | K28: =(J27+K27)/2 | L28: =(K27+L27)/2 | M28: =(L27+M27)/2
A29: Notes to Financial statements | B29: 1 to 23
A31: As per our report of even date
A32: For O M N & Associates
A33: Chartered Accountants
A34: ( Firm regn. No. 000383S)
D35: Director
D36: G Krishna
A37: Om Prakash Bang | D37: DIN: 03336421
A38: Partner
A39: Membership No. 018948
A40: Place: Hyderabad | D40: Director
A41: Date : 21-09-2023 | D41: G Krupan
D42: DIN : 03363685

Sheet CFS
A1: RAMSON AND GRANDSON JEWELLERS PRIVATE LIMITED
A2: CASH FLOW STATEMENT AS AT 31-03-2023
A3: Pariculars | B3: AS AT 31st March 2023 | C3: AS AT 31st March 2022 | D3: AS AT 31st March 2021 | E3: AS AT 31st March 2020
A4: I. Cash From Operating Activities
A5: Net Profit before tax | B5: ='P&L'!C20 | C5: ='P&L'!D20 | D5: =[1]PL!C21
A6: Adjustments for
A7: Depreciation | B7: ='P&L'!C17 | C7: ='P&L'!D17 | D7: =[1]PL!C18
A8: Add:Appropriations- GST refund received
A9: Loss / (Profit) on Sale of Asset
A10: Financial Charges | C10: ='P&L'!D16 | D10: =[1]PL!C17
A11: Operating Profit before working capital changes | B11: =SUM(B5:B10) | C11: =SUM(C5:C10) | D11: =SUM(D5:D10) | E11: =SUM(E5:E10)-1
A12: Increase / Decrease in Working Capital
A13: (Increase) / Decrease in Inventories | B13: =BS!D23-BS!C23 | C13: =BS!E23-BS!D23 | D13: =[1]BS!D23-[1]BS!C23
A14: (Increase) / Decrease in Sundry Debtors | B14: =BS!D24-BS!C24 | C14: =BS!E24-BS!D24 | D14: =[1]BS!D24-[1]BS!C24
A15: (Increase) / Decrease in Loans & Advances
A16: (Increase) / Decrease in Other Current Assets | B16: =BS!D26-BS!C26 | C16: =BS!E26-BS!D26 | D16: =[1]BS!D26-[1]BS!C26
A17: Increase / (Decrease) in Creditors | B17: =BS!C12-BS!D12 | C17: =BS!D12-BS!E12 | D17: =[1]BS!C12-[1]BS!D12
A18: Increase / (Decrease) in Other Current Liabilities | B18: =BS!C13-BS!D13 | C18: =BS!D13-BS!E13 | D18: =[1]BS!C13-[1]BS!D13
A19: Cash Generated/Used in Operations | B19: =SUM(B11:B18) | C19: =SUM(C11:C18) | D19: =SUM(D11:D18) | E19: =SUM(E11:E18)
A20: Income Tax Paid | B20: =-'P&L'!C22 | C20: =-'P&L'!D22 | D20: =-[1]PL!C23
A21: Income Tax of Prev Year
A22: Expenses Pertaing to PrevYear
A23: Net Cash Flow From Operating Activities - I
A24: II. Cash From Investing Activities:
A25: Proceeds from Sale of Fixed Assets
A26: Purchase of Fixed Assets | B26: =-'Com Dep'!C13 | C26: =-'Com Dep'!C14 | D26: =-'[1]Dep as per Com Act'!C13
A27: Increase in Investments | D27: =[1]BS!D20-[1]BS!C20
A28: Sale of Investments
A29: Interest Received on Deposits
A30: Net Cash Flow From Investing Activities - II | B30: =SUM(B20:B29) | C30: =SUM(C20:C29) | D30: =SUM(D20:D29) | E30: =SUM(E20:E29)
A31: III. Cash From Financing Activities
A32: Increase / (decrease) in Secured Loans | B32: =BS!C10-BS!D10 | C32: =BS!D10-BS!E10 | D32: =[1]BS!C10-[1]BS!D10
A33: (Increase)/decrease in long term loans and advances | B33: =BS!D21-BS!C21 | C33: =BS!E21-BS!D21 | D33: =[1]BS!D21-[1]BS!C21
A34: Foreign Exchange Fluctuations
A35: Financial Charges | C35: =-'P&L'!D16 | D35: =-[1]PL!C17
A36: Net Cash Flow From Financing Activities - III | B36: =SUM(B32:B35) | C36: =SUM(C32:C35) | D36: =SUM(D32:D35) | E36: =SUM(E32:E35)
A37: Increase /(decrease) in cash & cash equivalent ( I+II+III ) | B37: =B19+B30+B36 | C37: =C19+C30+C36-1 | D37: =D19+D30+D36 | E37: =E19+E30+E36
A38: Reconciliation :
A39: Cash & Cash Equivalents at the beginning of the year | B39: =BS!D25 | C39: =BS!E25 | D39: =[1]BS!D25
A40: Closing Cash & Cash Equivalents at the end of the year | B40: =BS!C25 | C40: =BS!D25 | D40: =[1]BS!C25
...

Sheet P&L
A1: RAMSON AND GRANDSON JEWELLERS PRIVATE LIMITED
A2: PROFIT AND LOSS STATEMENT FOR THE YEAR ENDED 31-03-2023
A4: Particulars | B4: Note No. | C4: AS AT 31st March 2023 | D4: AS AT 31st March 2022 | E4: AS AT 31st March 2021 | F4: AS AT 31st March 2020
A5: I. Revenue from operations | C5: =Notes!D95 | D5: =Notes!F95 | E5: =[1]Notes!D86 | F5: =[1]Notes!F86
A6: II.Other income | C6: ='Sub Grouping'!D26 | E6: =[1]TB2021!O125+[1]TB2021!O123
A7: Total Revenue ( I + II ) | C7: =SUM(C5:C6) | D7: =SUM(D5:D6) | E7: =SUM(E5:E6) | F7: =SUM(F5:F6)
A9: III. Expenses | J9: =C7-C10-C13
A10: (a)Purchase of stock in trade | C10: =Notes!D96 | D10: =Notes!F96 | F10: =[1]Notes!F87
A11: (b) Loss in commodities derevatives ( Hedging )
A12: (b)Changes in inventories of
A13: stock in trade. | C13: =Notes!D101 | D13: =Notes!F101 | F13: =[1]Notes!F92
A14: ( c ) Emloyee benefits expense | C14: =Notes!D106 | D14: =Notes!F106 | F14: =[1]Notes!F97
A16: (d) Finance cost | E16: =[1]TB2021!N138
A17: (e) Depreciation | C17: ='Com Dep'!H13 | D17: ='Com Dep'!H14
A18: (f) Other expenses | C18: =Notes!D121 | D18: =Notes!F121 | F18: =[1]Notes!F112
A19: Total Expenses | C19: =SUM(C10:C18) | D19: =SUM(D10:D18) | E19: =SUM(E10:E18) | F19: =SUM(F10:F18)
A20: Profit before Tax | C20: =C7-C19 | D20: =D7-D19 | F20: =F7-F19
A21: Tax Expenses
A22: Current Tax | C22: ='IT Dep'!H63
A23: Deffered Tax
A24: Profit after tax | C24: =C20-C22+C23 | D24: =D20-D22-D23 | E24: =E20-E22-E23 | F24: =F20-F22-F23
A25: Earning per equity share of face value of Rs. 10each
A26: Significant accounting policies
A27: Notes to Financial statements | B27: 1 to 23
A28: As per our report of even date
A29: =BS!A32
A30: Chartered Accountants
A31: ( Firm regn. No. 000383S) | D31: Director
D32: G Krishna
D33: DIN: 03336421
A34: Om Prakash Bang | F34: Director
A35: Partner
A36: Membership No. 018948
A37: Place: Hyderabad | D37: Director
A38: =BS!A41 | D38: G Krupan
D39: DIN : 03363685

Sheet IT Dep
B2: Attachment I
A3: M/S. RAMSON AND GRANDSON JEWELLERS (P) lTD
B4: Particulars | E4: ADDITION | I4: DEPRECIATION
A5: Sl. | C5: Date when | D5: W.D.V.as on | E5: UPTO | F5: AFTER | G5: SALE | H5: TOTAL | I5: Rate of | J5: 100% on. | K5: 50% on. | L5: Total | M5: W.D.V.
A6: no | C6: Put to use | D6: 1.4.2020 | E6: 30.9.2020 | F6: 30.9.2020 | H6: 31.03.2021 | I6: dep. | J6: op.bal.& add | K6: add.after | M6: as on
J7: upto 30.9.20 | K7: 30.9.20 | M7: 31.03.2021
B9: Computer | H9: =D9+E9+F9-G9 | J9: =D9*I9 | L9: =J9+K9 | M9: =H9-L9
B10: Computer software(Tally) | H10: =D10+F10 | J10: =D10*I10 | K10: =F10*I10/2 | L10: =J10+K10 | M10: =H10-L10
E11: =E10 | F11: =SUM(F9:F10) | H11: =SUM(H9:H10) | J11: =D11*I11 | K11: =SUM(K9:K10) | L11: =J11+K11 | M11: =H11-L11
B13: LED | H13: =D13+E13+F13 | J13: =(D13+E13)*I13 | L13: =J13+K13 | M13: =H13-L13
B14: Inverter | H14: =D14+E14+F14 | J14: =(D14+E14)*I14 | L14: =J14+K14 | M14: =H14-L14
B15: Buffing & Drilling Machine | H15: =D15+E15+F15 | J15: =(D15+E15)*I15 | L15: =J15+K15 | M15: =H15-L15
B16: Melting Machine | H16: =D16+E16+F16 | J16: =(D16+E16)*I16 | L16: =J16+K16 | M16: =H16-L16
B17: Wire Drawing Machine | H17: =D17+E17+F17 | J17: =(D17+E17)*I17 | L17: =J17+K17 | M17: =H17-L17
B18: Air Conditioner | H18: =D18+E18+F18 | J18: =(D18+E18)*I18 | L18: =J18+K18 | M18: =H18-L18
B19: Cars | H19: =D19+E19+F19 | J19: =(D19+E19)*I19 | L19: =J19+K19 | M19: =H19-L19
B20: Weighing Machine | H20: =D20+E20+F20 | J20: =(D20+E20)*I20 | L20: =J20+K20 | M20: =H20-L20
B21: Counting Machine | H21: =D21+E21+F21 | J21: =(D21+E21)*I21 | L21: =J21+K21 | M21: =H21-L21
B22: Samsung Phone | H22: =D22+E22+F22 | J22: =(D22+E22)*I22 | L22: =J22+K22 | M22: =H22-L22
B23: Refrigerator | H23: =D23+E23+F23 | J23: =(D23+E23)*I23 | L23: =J23+K23 | M23: =H23-L23
B24: Printer (HP 120) | H24: =D24+E24+F24 | J24: =(D24+E24)*I24 | L24: =J24+K24 | M24: =H24-L24
B25: Water Dispenser | H25: =D25+E25+F25 | J25: =(D25+E25)*I25 | L25: =J25+K25 | M25: =H25-L25
B26: Camera | H26: =D26+E26+F26 | J26: =(D26+E26)*15% | K26: =F26*I26/2 | L26: =J26+K26 | M26: =H26-L26
B27: Coffee Machine | H27: =D27+E27+F27 | J27: =(D27+E27)*I27 | L27: =J27+K27 | M27: =H27-L27
B28: EPABX (Telephone) | H28: =D28+E28+F28 | J28: =(D28+E28)*I28 | L28: =J28+K28 | M28: =H28-L28
B29: Television | H29: =D29+E29+F29 | J29: =(D29+E29)*I29 | L29: =J29+K29 | M29: =H29-L29
B30: Cell Phone | H30: =D30+E30+F30 | J30: =(D30+E30)*I30 | K30: =F30*I30/2 | L30: =J30+K30 | M30: =H30-L30
B31: UV Disinfection Machine | H31: =D31+E31+F31 | J31: =(D31+E31)*I31 | L31: =J31+K31 | M31: =H31-J31
E32: =SUM(E13:E31) | F32: =SUM(F13:F31) | H32: =SUM(H13:H31) | J32: =SUM(J13:J31) | K32: =SUM(K15:K30) | L32: =SUM(L13:L31) | M32: =H32-L32
B34: Furniture | H34: =D34+E34+F34 | J34: =(D34+E34)*I34 | K34: =F34*5% | L34: =J34+K34 | M34: =H34-L34
B35: Total | D35: =D11+D32+D34 | E35: =E11+E32+E34 | F35: =F11+F32+F34 | G35: =G11+G32+G34 | H35: =H11+H32+H34 | J35: =J11+J32+J34 | K35: =K11+K32+K34 | L35: =L11+L32+L34 | M35: =M11+M32+M34
J39: Director | L39: Director
B42: Calculation of Deferred Tax Assets/Liability as per Depreciation Method : | D42: 2022-23
D43: Amount.(Rs.)
B44: Depreciation as per IT Act as | C44: A | D44: =L32
B45: Depreciation as per Companies Act | C45: B | D45: ='Com Dep'!H13
B46: Timing Difference in Depreciation | C46: C( A-B) | D46: =D44-D45
B47: Deffered Tax LIABILITY(Current Year) | C47: D | D47: =D46*26%
B48: Deffered Tax Asset(Previous Year) (Net) | C48: E
B49: Deffered tax liability B/F
...

Sheet Com Dep
A1: RAMSON AND GRANDSON JEWELLERS PRIVATE LIMITED
A2: F.Y 2022-23
A3: Note no. 7 - Fixed Assets
B5: Gross Block | G5: Depreciation | K5: Net Block
A6: Particulars | B6: As at 01-04-2022 | C6: Additions | D6: Deletions | E6: Adjustment | F6: As At | G6: upto | H6: During | I6: Adjustment | J6: upto | K6: As at | L6: As at
F7: 31.03.2023 | G7: 01.04.2022 | H7: the year | J7: 31-03-2023 | K7: 31-03-23 | L7: 31-03-22
A8: TANGIBLE ASSETS
A9: I.COMPUTERS AND DATA PROCESSING UNITS | F9: =B9+C9-D9 | H9: =S31 | J9: =G9+H9+I9 | K9: =F9-J9
A10: II.PlANT AND MACHINERY | F10: =B10+C10-D10 | H10: =S36 | J10: =G10+H10 | K10: =F10-J10
A11: III.OFFICE EQUIPMENT | F11: =B11+C11 | H11: =S64 | J11: =G11+H11 | K11: =F11-J11
A12: IV. FURNITURE AND FIXTURES | F12: =B12+C12-D12 | H12: =S71 | J12: =G12+H12 | K12: =F12-J12
B13: =SUM(B9:B12) | C13: =SUM(C9:C12) | D13: =SUM(D9:D12) | E13: =SUM(E9:E12) | F13: =SUM(F9:F12) | G13: =SUM(G9:G12) | H13: =SUM(H9:H12) | I13: =SUM(I9:I12) | ... L13: =SUM(L9:L12) | N13: =L13+C13
A14: PREVIOUS YEAR
H17: Director | J17: Director
A22: **Depreciation is Calculated on SLM Basis
A24: Block (Old) | B24: Block of Asset as per 2013 | C24: Head of Asset | D24: Date of purchase | E24: Cost Capitalised | F24: WDV as on 31-03-2019 | G24: Depr for the FY 2017-18 | H24: WDV as on 31-03-2018 | I24: Value of Asset after Additions & Deletions during the Year | J24: Depr for the FY 2018-19 | K24: WDV as on 31-03-2019 | L24: For additions during the year=(value of the asset/total useful no. of days)*no. of days asset used during the year | M24: Depr for the FY 2019-20 | N24: WDV as at 31-03-2020 | O24: Depr for the FY 2020-21 | P24: WDV as at 31-03-2021 | Q24: Depr for the FY 2021-22 | R24: WDV as at 31-03-2022 | S24: Depr for the FY 2022-23 | T24: WDV as at 31-03-2023 | U24: working 5% | V24: working
A25: I.COMPUTERS AND DATA PROCESSING UNITS
A26: Tally Software | B26: End user devices | C26: Tally Software | D26: 42832 | H26: =E26-G26 | J26: =17096+L26 | K26: =H26+I26-J26 | L26: =(I26/(3*365))*347 | N26: =K26-M26 | P26: =N26-O26
A27: Computers | B27: End user devices | C27: Computers | D27: 41859 | F27: =G27+H27
A28: Computers | B28: End user devices | C28: Computers | D28: 44557 | Q28: =60931*94/365 | R28: =E28-Q28 | T28: =R28-S28 | U28: =E28*5% | V28: =(E28-U28)/3
E31: =SUM(E25:E30) | F31: =SUM(F26:F27) | G31: =SUM(G26:G27) | H31: =SUM(H26:H27) | J31: =SUM(J26:J27) | K31: =SUM(K26:K27) | M31: =SUM(M26:M27) | N31: =SUM(N26:N27) | O31: =SUM(O26:O27) | P31: =SUM(P26:P27) | Q31: =SUM(Q26:Q30) | R31: =SUM(R26:R30) | S31: =SUM(S26:S30) | T31: =SUM(T26:T30)
A32: II.PLANT AND MACHINERY* | N32: =K32-M32
A33: Buffing & Drilling Machine | B33: Plant & Machinery | C33: Buff machine | D33: 42991 | H33: =E33-G33 | J33: =(E33/(15*365))*365 | K33: =H33-J33 | N33: =K33-M33 | P33: =N33-O33 | R33: =P33-Q33 | T33: =R33-S33 | U33: =E33*5%
A34: Melting Machine | B34: Plant & Machinery | C34: Melting Machine | D34: 42957 | H34: =E34-G34 | J34: =(E34/(15*365))*365 | K34: =H34-J34 | N34: =K34-M34 | P34: =N34-O34 | R34: =P34-Q34 | T34: =R34-S34 | U34: =E34*5%
A35: Wire Drawing Machine | B35: Plant & Machinery | C35: Wire Drawing Machine | D35: 43013 | H35: =E35-G35 | J35: =(E35/(15*365))*365 | K35: =H35-J35 | N35: =K35-M35 | P35: =N35-O35 | R35: =P35-Q35 | T35: =R35-S35 | U35: =E35*5%
E36: =SUM(E33:E35) | G36: =SUM(G33:G35) | H36: =SUM(H33:H35) | I36: =SUM(I33:I35) | J36: =SUM(J33:J35) | K36: =SUM(K33:K35) | N36: =K36-M36 | O36: =SUM(O33:O35) | P36: =SUM(P33:P35) | Q36: =SUM(Q33:Q35) | R36: =SUM(R33:R35) | S36: =SUM(S33:S35) | T36: =SUM(T33:T35)
A37: III.OFFICE EQUIPMENT | N37: =K37-M37
A38: Air Conditioner | B38: Office Equipment | C38: Air Conditioner | D38: 41639 | F38: =G38+H38 | J38: =H38
A39: Weighing Machine | B39: Office Equipment | C39: Weighing Machine | F39: =G39+H39 | J39: =H39
A40: Counting Machine | B40: Office Equipment | C40: Counting Machine | D40: 25-07-2012 | F40: =G40+H40 | N40: =K40-M40
A41: Counting Machine | B41: Office Equipment | C41: Counting Machine | D41: 41859 | F41: =G41+H41 | J41: =G41 | K41: =H41-J41 | N41: =K41-M41
A42: Printer (HP 120) | B42: Office Equipment | C42: Printer (HP 120) | D42: 17-05-2014 | F42: =G42+H42 | J42: =G42 | K42: =H42+I42-J42 | N42: =K42-M42
A43: Water Dispenser | B43: Office Equipment | C43: Water Dispenser | D43: 41675 | F43: =G43+H43 | J43: =G43 | K43: =H43-J43 | N43: =K43-M43
A44: Camera | B44: Office Equipment | C44: Camera | D44: 42038 | F44: =G44+H44 | J44: =G44 | K44: =H44-J44 | N44: =K44-M44
A45: Coffee Machine | B45: Office Equipment | C45: Coffee Machine | D45: 41739 | F45: =G45+H45 | J45: =G45 | K45: =H45-J45 | N45: =K45-M45
A46: EPABX (Telephone) | B46: Office Equipment | C46: EPABX (Telephone) | D46: 41780 | F46: =G46+H46 | J46: =G46 | K46: =H46-J46 | N46: =K46-M46
A47: Television | B47: Office Equipment | C47: Television | D47: 41852 | F47: =G47+H47 | J47: =G47 | K47: =H47-J47 | N47: =K47-M47
A48: Cell Phone Samsung | B48: Office Equipment | C48: Cell phone | D48: 43673 | N48: =I48-M48 | P48: =N48-O48 | R48: =P48-Q48 | T48: =R48-S48 | U48: =I48*5% | V48: =(I48-U48)/5
A49: Cell Phone Samsung | B49: Office Equipment | C49: Cell Phone | D49: 43689 | N49: =I49-M49 | P49: =N49-O49 | R49: =P49-Q49 | T49: =R49-S49 | U49: =I49*5% | V49: =(I49-U49)/5
A50: Printer | B50: Office Equipment | D50: 44008 | P50: =I50-O50 | R50: =P50-Q50 | T50: =R50-S50 | U50: =I50*5% | V50: =(I50-U50)/5
...
